Workbook
Name L_Transitaria: LISTAS!$A$5:$A$7
Name L_Region: LISTAS!$B$5:$B$7
Name L_SiNo: LISTAS!$C$5:$C$6
Name L_Prorrateo: LISTAS!$D$5:$D$6
Name L_BaseCom: LISTAS!$E$5:$E$6
Name L_Estado: LISTAS!$F$5:$F$6
Name L_TipoCont: LISTAS!$G$5:$G$8
Name L_Grupo: LISTAS!$H$5:$H$6
Name L_Centro: LISTAS!$I$5:$I$8
Name L_Elemento: LISTAS!$J$5:$J$10
Name L_TipoActivo: LISTAS!$K$5:$K$7
Name L_Territorio: LISTAS!$L$5:$L$21
Name L_TerrRegion: LISTAS!$M$5:$M$21
Name Empresa: PARAMETROS!$C$6
Name Fecha_Inicio: PARAMETROS!$C$7
Name Metodo_Prorrateo: PARAMETROS!$C$8
Name Base_Comision: PARAMETROS!$C$9
Name Tolerancia_Comb: PARAMETROS!$C$10
Name Mes_Corte: PARAMETROS!$C$11
Name Std_Viajes_Puerto: PARAMETROS!$C$13
Name Litros_Puerto_Viaje: PARAMETROS!$C$14
Name Km_Puerto_Viaje: PARAMETROS!$C$15
Name Rend_Desagrupe: PARAMETROS!$C$16
Name Rend_Desagrupe_CT: PARAMETROS!$C$17
Name Cap_Camion_OCC: PARAMETROS!$C$18
Name Cap_Camion_CEN: PARAMETROS!$C$19
Name Cap_Camion_ORI: PARAMETROS!$C$20
Name L_Dist_OCC: PARAMETROS!$C$21
Name L_Tras_CEN: PARAMETROS!$C$22
Name L_Dist_CEN: PARAMETROS!$C$23
Name L_Tras_ORI: PARAMETROS!$C$24
Name L_Dist_ORI: PARAMETROS!$C$25
Name Pct_Reclamaciones: PARAMETROS!$C$27
Name Pct_Banco: PARAMETROS!$C$28
Name Imp_Ventas_Serv: PARAMETROS!$C$30
Name Contrib_Territorial: PARAMETROS!$C$31
Name Contrib_SS: PARAMETROS!$C$32
Name Imp_Fuerza_Trabajo: PARAMETROS!$C$33
Name Imp_Utilidades: PARAMETROS!$C$34

Sheet INICIO
B2: ANÁLISIS DE RENTABILIDAD – NEGOCIO DE PAQUETERÍA
B3: =Empresa&" · Modelo por contenedor, por región y por mes · Importes en USD" -> Empresa de Paquetería (editar) · Modelo por contenedor, por región y por mes · Importes en USD
B5: Flujo modelado
B6: 1. PUERTO (vehículo propio: cita, combustible, dieta, desgaste) → 2. TRANSITARIA ENCI / A.V (desagrupe por jornal) → 3. DISTRIBUCIÓN: Occidente directa · Centro y Oriente con traslado, centro transitorio y distribución → 4. COMERCIALIZACIÓN (21 gestores: fijo + variable)
B8: Hojas del libro
B9: Hoja | C9: Contenido | D9: Cuándo se usa
B10: GUIA_USO | C10: Resumen de la guía (la guía completa con imágenes es el PDF que acompaña al libro). | D10: Antes de empezar
B11: ANALISIS | C11: Diagnóstico, metodología, clasificación de costos y propuestas de mejora. | D11: Para decidir
B12: PARAMETROS | C12: Normas técnicas, porcentajes, tributos y métodos de cálculo. | D12: Una vez / si cambia una norma
B13: PRECIOS | C13: Tarifas y precios con fecha de vigencia (historial auditable). | D13: Una vez / si cambia un precio
B14: ACTIVOS | C14: Vehículos y equipos: depreciación, mantenimiento y seguros. | D14: Una vez / al comprar o vender
B15: COSTOS_FIJOS | C15: Costos fijos mensuales por centro de costo y tributos sobre salarios. | D15: Una vez / cierre de mes
B16: COMERCIAL | C16: 21 gestores: pago fijo, liquidación variable y conciliación mensual. | D16: Cierre de mes
B17: ENTRADA | C17: Registro de contenedores: la hoja donde se trabaja a diario. | D17: Con cada contenedor
B18: CALCULO | C18: Cálculo automático completo por contenedor y por región. | D18: Solo consulta
B19: RESUMEN_MES | C19: Rentabilidad mensual, punto de equilibrio e impuesto anual estimado. | D19: Cierre de mes
B20: DASHBOARD | C20: Panel de indicadores y gráficos del período elegido. | D20: Para informar
... B22: LISTAS | C22: Listas de los desplegables (técnica). | D22: No se toca
B24: Su rutina de trabajo (una sola persona lleva el libro)
B25: Una sola vez, al empezar | C25: PARAMETROS → PRECIOS → ACTIVOS → COSTOS_FIJOS → COMERCIAL. Después, borrar los datos de ejemplo.
B26: Con cada contenedor | C26: ENTRADA: 1) al llegar, ID, fecha, transitaria y kg por región; 2) al terminar la distribución, datos reales y Estado «Cerrado».
B27: Cuando cambia un precio | C27: PRECIOS: agregar una fila nueva con la fecha desde la que rige. Nunca sobrescribir la anterior.
B28: Cada fin de mes | C28: Revisar alertas en INICIO → gastos reales en COSTOS_FIJOS → liquidación en COMERCIAL → RESUMEN_MES y DASHBOARD → guardar una copia con fecha.
B30: Leyenda de colores
B31: 1.234 | C31: Dato de entrada: se puede escribir (letra azul, fondo amarillo).
B32: 1234 | C32: Fórmula: no escribir (letra negra).
B33: 1234 | C33: Enlace a otra hoja (letra verde).
B35: Estado del libro (controles automáticos)
B36: Contenedores registrados | C36: =COUNTIF(ENTRADA!$B$6:$B$305,"?*") -> 4
B37: Contenedores con alertas | C37: =COUNTIF(CALCULO!$CT$6:$CT$305,"?*") -> 1
B38: Contenedores abiertos (sin cerrar) | C38: =COUNTIF(CALCULO!$F$6:$F$305,"Abierto") -> 1
B39: Cuadre de regiones (CALCULO) | C39: =IF(AND(MAX(CALCULO!$CO$6:$CO$305)<0.01,MIN(CALCULO!$CO$6:$CO$305)>-0.01),"OK","REVISAR") -> OK
B40: Cuadre mensual (RESUMEN_MES) | C40: =IF(AND(MAX(RESUMEN_MES!$AA$6:$AA$29)<0.01,MIN(RESUMEN_MES!$AA$6:$AA$29)>-0.01),"OK","REVISAR") -> OK
B41: Conciliación de comercialización | C41: =COMERCIAL!G39 -> CUADRA
B42: Utilidad antes de impuesto acumulada | C42: =RESUMEN_MES!O30 -> 9168.3167
B45: Los datos que contiene el libro son de EJEMPLO para mostrar su funcionamiento. Sustitúyalos siguiendo la guía en PDF (capítulo «Preparar el libro con sus datos»).

Sheet GUIA_USO
B2: GUÍA DE USO (RESUMEN)
B4: Este libro calcula de forma automática cuánto gana o pierde la empresa con cada contenedor de paquetería, en cada región y en cada mes. Lo lleva UNA sola persona, que solo escribe datos en las celdas de entrada (amarillas, letra azul). Todo lo demás se calcula con fórmulas. La guía completa, con imágenes y ejercicios paso a paso, es el PDF «Guia_de_Uso_Rentabilidad_Paqueteria.pdf» que acompaña a este archivo.
B6: 1. Colores y convenciones
B7: Aspecto de la celda | C7: Significado | D7: ¿Se puede escribir?
B8: Fondo amarillo claro, letra azul | C8: Dato de entrada (valor que usted escribe) | D8: SÍ
B9: Letra negra | C9: Fórmula de cálculo | D9: NO
B10: Letra verde | C10: Enlace a otra hoja | D10: NO
B11: Fondo gris en encabezados | C11: Títulos de columnas y secciones | D11: NO
B12: Celda vacía en columnas «(opcional)» | C12: El libro usa la norma técnica de PARAMETROS | D12: Sí, si hay dato real
B14: Las hojas están protegidas sin contraseña para evitar borrar fórmulas por error. Si necesita modificar la estructura: Revisar > Desproteger hoja. Vuelva a protegerla al terminar.
B16: 2. Configuración inicial (una sola vez)
B17: 1. PARAMETROS: escriba el nombre de la empresa, el primer mes del período (Fecha_Inicio) y revise las normas técnicas: litros por viaje, kilómetros, capacidad de los camiones y rendimiento del desagrupe (kg por jornal). Revise también los porcentajes de reclamaciones, de comisiones bancarias y las tasas tributarias.
B18: 2. PRECIOS: en la primera fila escriba las tarifas por kg que cobra la empresa en cada región, el precio del diésel, la cita del puerto, la dieta, el pago por jornal y las comisiones de comercialización, con la fecha desde la que rigen.
B19: 3. ACTIVOS: registre cada vehículo propio y cada equipo con su fecha de alta, valor de compra, valor residual y vida útil. El libro calcula la depreciación mensual y deja de calcularla al terminar la vida útil o en la fecha de baja.
B20: 4. COSTOS_FIJOS: escriba en la columna «Valor base mensual» cada gasto fijo (salarios de oficina, alquiler, electricidad, servicios contratados de chofer y ayudante por región, etc.). Indique si es salario de un trabajador propio («Sí» en la columna correspondiente): así se calculan la seguridad social (14 %) y el impuesto por la utilización de la fuerza de trabajo (5 %).
B21: 5. COMERCIAL: escriba los nombres de los 21 gestores (5 del grupo central y 16 provinciales) y el pago fijo mensual de cada uno. El total pasa solo a COSTOS_FIJOS.
B22: 6. Borre los datos de EJEMPLO de las hojas ENTRADA, PRECIOS, ACTIVOS y COMERCIAL. Seleccione las celdas y pulse la tecla Supr. NUNCA elimine filas ni columnas.
B23: 3. Registro de cada contenedor (hoja ENTRADA)
B24: Use una fila por contenedor. Los datos se registran en dos momentos:
B26: 1. Al recibir el contenedor: ID del contenedor, fecha de arribo, transitaria (ENCI o A.V), tipo, número de bultos y kg que van a cada región (Occidente, Centro, Oriente), según el manifiesto o desglose. Ponga el Estado en «Abierto».
B27: 2. Al terminar la distribución, escriba los datos REALES que tenga: viajes y litros al puerto, dieta pagada, jornales del desagrupe, litros de traslado y de distribución por región, jornales de los centros transitorios, cargos por estadía o almacenaje, otros gastos directos con su detalle y otros ingresos. Ponga la fecha de fin de la distribución y cambie el Estado a «Cerrado».
... B40: 6. Cómo leer los resultados
B41: Indicador | C41: Qué significa | D41: Cómo se calcula
B42: Margen de contribución (MC) | C42: Lo que queda de los ingresos para cubrir los costos fijos | D42: Ingresos − costos variables
B43: Utilidad antes de impuesto (UAI) | C43: Ganancia o pérdida después de todos los costos y de los tributos sobre ingresos | D43: MC − costos fijos − impuesto sobre ventas y servicios − contribución territorial
B44: Utilidad neta estimada | C44: Ganancia después del impuesto sobre utilidades (estimado) | D44: UAI − 35 % de la UAI positiva
B45: Costo total por kg | C45: Lo que cuesta mover 1 kg de punta a punta | D45: Costos totales ÷ kg
B46: Punto de equilibrio (kg) | C46: kg mínimos del mes para no perder dinero | D46: Costos fijos ÷ (MC − tributos sobre ingresos) por kg
B47: Margen de seguridad | C47: Cuánto pueden caer los kg antes de entrar en pérdida | D47: (kg reales − kg de equilibrio) ÷ kg reales
B48: Fijos no absorbidos | C48: Costos fijos del mes que ningún contenedor cubrió (meses sin arribos o regiones sin carga) | D48: Fijos del mes − fijos asignados a contenedores
B49: Tarifa mínima (SIMULADOR) | C49: Precio por kg por debajo del cual la región pierde dinero | D49: Costos de la región ÷ kg ajustados por los % sobre ingreso
B51: • Utilidad de una región: ingresos de la región menos sus costos propios (combustible, desagrupe, comisión y fijos regionales), menos su parte de los costos compartidos (puerto, transitaria, fijos generales) según sus kg.
B52: • El impuesto sobre utilidades es una ESTIMACIÓN. La liquidación oficial es anual: use la tabla anual de RESUMEN_MES y valídela con el contador y la ONAT.
B53: 7. Simulador («¿qué pasaría si...?»)
B54: En SIMULADOR la columna «Valor actual» trae los datos reales del libro. Escriba un valor en «Valor a simular» para probar un escenario: subir la tarifa, subir el diésel, recibir más contenedores, etc. Borre el valor para volver al dato real. Las tablas de sensibilidad muestran la utilidad mensual para distintas tarifas, precios del diésel y cantidades de contenedores. El simulador no modifica ningún dato del libro.
B56: 8. Alertas y cómo resolverlas
B57: Alerta | C57: Causa | D57: Qué hacer
B58: Falta fecha / Falta transitaria | C58: Dato obligatorio vacío | D58: Complete la columna en ENTRADA
B59: Mes fuera del rango de COSTOS_FIJOS | C59: La fecha cae fuera de los 24 meses del período | D59: Corrija la fecha, o cambie Fecha_Inicio en PARAMETROS al comenzar un nuevo período (guarde antes una copia)
B60: Sin kg | C60: No se registraron kg por región | D60: Escriba los kg de Occidente, Centro y Oriente
...

Sheet ANALISIS
B1: Fuentes de tributos y combustible: ver README (enlaces). Valores ILUSTRATIVOS marcados en PARAMETROS y PRECIOS.
B2: ANÁLISIS ECONÓMICO Y PROPUESTA
B4: Objetivo: medir con rigor la rentabilidad del negocio de paquetería por contenedor, por región y por mes; identificar dónde se gana y dónde se pierde dinero; y dar a la dirección indicadores para decidir tarifas, rutas y volumen.
B6: 1. Diagnóstico del flujo actual
B7: Etapa | C7: Actividad | D7: Recurso | E7: Costos identificados | F7: Comportamiento
B8: 1. Puerto | C8: Recogida del contenedor en el muelle | D8: Vehículo PROPIO | E8: Cita (10 USD), 60 L de combustible, dieta del chofer, desgaste, depreciación, mantenimiento | F8: Variable por viaje + fijo mensual
B9: 2. Transitaria (ENCI / A.V) | C9: Desagrupe y clasificación por destinatario | D9: Mano de obra por jornada | E9: Jornales; posibles cargos de la transitaria, almacenaje y estadía | F9: Variable por kg / contenedor
B10: 3a. Occidente | C10: Distribución directa | D10: Servicio contratado a terceros | E10: Chofer y ayudante (pago fijo mensual) + combustible de distribución | F10: Fijo mensual + variable
B11: 3b. Centro y Oriente | C11: Traslado a centro transitorio, desagrupe y distribución | D11: Servicio contratado a terceros | E11: Chofer y ayudante + combustible de traslado + jornales de desagrupe + combustible de distribución | F11: Fijo mensual + variable
B12: 4. Comercialización | C12: Gestión y cobro en 16 territorios + grupo central de 5 | D12: 21 gestores | E12: Pago fijo igual para todos + parte variable según lo gestionado | F12: Fijo mensual + variable
B13: Transversal | C13: Dirección, contabilidad, local, servicios | D13: Estructura | E13: Salarios, alquiler, electricidad, comunicaciones, seguros, tributos | F13: Fijo mensual
B15: 2. Problemas de la medición actual
B16: • No se separan los costos fijos de los variables. Sin esa separación no se puede calcular el punto de equilibrio ni saber cuánto aporta cada kg.
B17: • Faltan costos ocultos: depreciación y mantenimiento del vehículo propio, tributos sobre ingresos y salarios, estadía y almacenaje del contenedor, mermas y reclamaciones, y comisiones bancarias. Por eso la rentabilidad aparente es MAYOR que la real.
B18: • Centro y Oriente tienen dos tramos de transporte y un segundo desagrupe. Con una tarifa por kg igual en todo el país, el Occidente probablemente subsidia al Oriente. Hoy no se puede ver.
B19: • No existen normas de consumo de combustible por ruta. Los desvíos (consumo excesivo, pérdidas) no se detectan.
B20: • Los precios cambian (el diésel en USD varía desde mayo de 2026) y no hay historial. Si se sobrescriben, se pierde el costo real de los contenedores anteriores.
B21: • La parte variable de la comercialización no se concilia con los kg o ingresos realmente entregados y cobrados.
B22: 3. Metodología del modelo propuesto
B23: • Costeo variable (direct costing) para decidir: margen de contribución por contenedor, por kg y por región, punto de equilibrio y margen de seguridad.
B24: • Costeo por absorción para conocer el costo completo: los costos fijos mensuales se reparten entre los contenedores del mes según sus kg o en partes iguales. Los fijos regionales se reparten solo entre los kg de esa región.
B25: • Centros de costo: Puerto, Transitaria, Occidente, Centro, Oriente, Comercialización y Generales. Cada costo tiene un inductor: viajes, kg, jornales, litros o ingreso.
B26: • Precios con vigencia (hoja PRECIOS): cada contenedor se valora con los precios de su fecha de arribo. El historial queda intacto y es auditable.
... B30: 4. Clasificación de costos
B31: Concepto | C31: Centro de costo | D31: Tipo | E31: Inductor | F31: Elemento de gasto
B32: Cita del puerto | C32: Puerto | D32: Variable | E32: Viaje | F32: Otros gastos monetarios
B33: Combustible al puerto | C33: Puerto | D33: Variable | E33: Litros (norma 60 L/viaje) | F33: Combustibles y lubricantes
B34: Dieta del chofer | C34: Puerto | D34: Variable | E34: Viaje | F34: Otros gastos monetarios
B35: Desgaste (neumáticos, lubricantes) | C35: Puerto | D35: Variable | E35: Km recorridos | F35: Materias primas y materiales
B36: Depreciación del vehículo propio | C36: Generales | D36: Fijo | E36: Mes (vida útil) | F36: Depreciación y amortización
B37: Mantenimiento preventivo, seguros y licencias | C37: Generales | D37: Fijo | E37: Mes | F37: Otros gastos monetarios
B38: Jornales de desagrupe (ENCI / A.V) | C38: Transitaria | D38: Variable | E38: Jornal (kg / rendimiento) | F38: Gastos de fuerza de trabajo
B39: Servicio de la transitaria, estadía y almacenaje | C39: Transitaria | D39: Variable | E39: Contenedor / días | F39: Otros gastos monetarios
B40: Chofer y ayudante (servicio contratado) | C40: Occidente / Centro / Oriente | D40: Fijo | E40: Mes | F40: Otros gastos monetarios
B41: Combustible de traslado y distribución | C41: Occidente / Centro / Oriente | D41: Variable | E41: Litros (viajes × norma) | F41: Combustibles y lubricantes
B42: Jornales de desagrupe en centro transitorio | C42: Centro / Oriente | D42: Variable | E42: Jornal | F42: Gastos de fuerza de trabajo
... B50: Impuesto sobre utilidades (35 %) | C50: Resultado | D50: Sobre utilidad | E50: Utilidad anual | F50: Tributo
B52: 5. Propuestas de mejora (ordenadas por impacto económico)
B53: # | C53: Propuesta | D53: Beneficio esperado | E53: Prioridad
B54: 1 | C54: Tarifa diferenciada por región (la hoja SIMULADOR calcula la tarifa mínima de cada región) | D54: Evita que Occidente subsidie a Centro y Oriente; protege el margen | E54: ALTA
...

Sheet DASHBOARD
A1: Panel de rentabilidad
A2: ="Empresa: "&Empresa -> Empresa: Empresa de Paquetería (editar)
B4: Período desde (mes) | C4: 46266 | D4: Elija el primer día del mes (dd/mm/aaaa) o seleccione de la lista.
B5: Período hasta (mes) | C5: 46296 | D5: =IF(C5<C4,"ATENCIÓN: «hasta» es anterior a «desde»","")
B7: INDICADOR | C7: VALOR | G7: INDICADOR | H7: VALOR
B8: Contenedores | C8: =SUMIFS(RESUMEN_MES!$B$6:$B$29,RESUMEN_MES!$A$6:$A$29,">="&$C$4,RESUMEN_MES!$A$6:$A$29,"<="&$C$5) -> 4 | G8: Margen neto % | H8: =IF(C10=0,0,C18/C10) -> 0.18490245
B9: kg distribuidos | C9: =SUMIFS(RESUMEN_MES!$F$6:$F$29,RESUMEN_MES!$A$6:$A$29,">="&$C$4,RESUMEN_MES!$A$6:$A$29,"<="&$C$5) -> 40100 | G9: Ingreso por kg | H9: =IF(C9=0,0,C10/C9) -> 0.80374065
B10: Ingresos | C10: =SUMIFS(RESUMEN_MES!$G$6:$G$29,RESUMEN_MES!$A$6:$A$29,">="&$C$4,RESUMEN_MES!$A$6:$A$29,"<="&$C$5) -> 32230 | G10: Costo total por kg | H10: =IF(C9=0,0,(C11+C14+C15)/C9) -> 0.57510432
B11: Costos variables | C11: =SUMIFS(RESUMEN_MES!$H$6:$H$29,RESUMEN_MES!$A$6:$A$29,">="&$C$4,RESUMEN_MES!$A$6:$A$29,"<="&$C$5) -> 13036.25 | G11: Utilidad antes de impuesto por kg | H11: =IF(C9=0,0,C16/C9) -> 0.22863633
B12: Margen de contribución | C12: =C10-C11 -> 19193.75 | G12: Utilidad media por contenedor | H12: =IF(C8=0,0,C16/C8) -> 2292.0792
B13: MC % | C13: =IF(C10=0,0,C12/C10) -> 0.59552436 | G13: Punto de equilibrio del período (kg) | H13: =IF(C9=0,"s/d",IF(C12-C15<=0,"No cubre",C14/((C12-C15)/C9))) -> 16605.692
B14: Costos fijos del período | C14: =SUMIFS(RESUMEN_MES!$K$6:$K$29,RESUMEN_MES!$A$6:$A$29,">="&$C$4,RESUMEN_MES!$A$6:$A$29,"<="&$C$5) -> 6480.1333 | G14: Punto de equilibrio (contenedores) | H14: =IF(ISNUMBER(H13),H13/(C9/C8),"s/d") -> 1.6564282
B15: Tributos sobre ingresos | C15: =SUMIFS(RESUMEN_MES!$N$6:$N$29,RESUMEN_MES!$A$6:$A$29,">="&$C$4,RESUMEN_MES!$A$6:$A$29,"<="&$C$5) -> 3545.3 | G15: Margen de seguridad | H15: =IF(ISNUMBER(H13),(C9-H13)/C9,"s/d") -> 0.58589296
B16: UTILIDAD ANTES DE IMPUESTO | C16: =C12-C14-C15 -> 9168.3167 | G16: Fijos no absorbidos (capacidad ociosa) | H16: =SUMIFS(RESUMEN_MES!$M$6:$M$29,RESUMEN_MES!$A$6:$A$29,">="&$C$4,RESUMEN_MES!$A$6:$A$29,"<="&$C$5) -> 0
B17: Impuesto sobre utilidades (estimado) | C17: =MAX(0,C16)*Imp_Utilidades -> 3208.9108 | G17: Contenedores con alerta (todo el libro) | H17: =COUNTIF(CALCULO!$CT$6:$CT$305,"?*") -> 1
B18: UTILIDAD NETA ESTIMADA | C18: =C16-C17 -> 5959.4058 | G18: Desvío medio del combustible | H18: =IFERROR(SUMIFS(CALCULO!$CQ$6:$CQ$305,CALCULO!$D$6:$D$305,">="&$C$4,CALCULO!$D$6:$D$305,"<="&$C$5)/SUMIFS(CALCULO!$CP$6:$CP$305,CALCULO!$D$6:$D$305,">="&$C$4,CALCULO!$D$6:$D$305,"<="&$C$5)-1,0) -> 0.0043307087
B20: Estructura de costos del período | G20: Rentabilidad por región del período
B21: Concepto | C21: USD | D21: % de los ingresos | E21: USD por kg | G21: Región | H21: kg | I21: Ingresos | J21: Utilidad antes de impuesto | K21: Margen %
B22: Puerto (vehículo propio) | C22: =SUMIFS(CALCULO!$Y$6:$Y$305,CALCULO!$D$6:$D$305,">="&$C$4,CALCULO!$D$6:$D$305,"<="&$C$5) -> 650.4 | D22: =IF($C$10=0,0,C22/$C$10) -> 0.020179957 | E22: =IF($C$9=0,0,C22/$C$9) -> 0.016219451 | G22: Occidente | H22: =SUMIFS(CALCULO!$G$6:$G$305,CALCULO!$D$6:$D$305,">="&$C$4,CALCULO!$D$6:$D$305,"<="&$C$5) -> 19700 | I22: =SUMIFS(CALCULO!$M$6:$M$305,CALCULO!$D$6:$D$305,">="&$C$4,CALCULO!$D$6:$D$305,"<="&$C$5) -> 15760 | J22: =SUMIFS(RESUMEN_MES!$W$6:$W$29,RESUMEN_MES!$A$6:$A$29,">="&$C$4,RESUMEN_MES!$A$6:$A$29,"<="&$C$5) -> 8420.2208 | K22: =IF(I22=0,0,J22/I22) -> 0.53427797
B23: Transitaria (desagrupe y estadía) | C23: =SUMIFS(CALCULO!$AE$6:$AE$305,CALCULO!$D$6:$D$305,">="&$C$4,CALCULO!$D$6:$D$305,"<="&$C$5) -> 765 | D23: =IF($C$10=0,0,C23/$C$10) -> 0.02373565 | E23: =IF($C$9=0,0,C23/$C$9) -> 0.019077307 | G23: Centro | H23: =SUMIFS(CALCULO!$H$6:$H$305,CALCULO!$D$6:$D$305,">="&$C$4,CALCULO!$D$6:$D$305,"<="&$C$5) -> 9100 | I23: =SUMIFS(CALCULO!$N$6:$N$305,CALCULO!$D$6:$D$305,">="&$C$4,CALCULO!$D$6:$D$305,"<="&$C$5) -> 7280 | J23: =SUMIFS(RESUMEN_MES!$X$6:$X$29,RESUMEN_MES!$A$6:$A$29,">="&$C$4,RESUMEN_MES!$A$6:$A$29,"<="&$C$5) -> 861.63433 | K23: =IF(I23=0,0,J23/I23) -> 0.11835636
B24: Distribución Occidente | C24: =SUMIFS(CALCULO!$AI$6:$AI$305,CALCULO!$D$6:$D$305,">="&$C$4,CALCULO!$D$6:$D$305,"<="&$C$5) -> 1260 | D24: =IF($C$10=0,0,C24/$C$10) -> 0.039094012 | E24: =IF($C$9=0,0,C24/$C$9) -> 0.031421446 | G24: Oriente | H24: =SUMIFS(CALCULO!$I$6:$I$305,CALCULO!$D$6:$D$305,">="&$C$4,CALCULO!$D$6:$D$305,"<="&$C$5) -> 11300 | I24: =SUMIFS(CALCULO!$O$6:$O$305,CALCULO!$D$6:$D$305,">="&$C$4,CALCULO!$D$6:$D$305,"<="&$C$5) -> 9040 | J24: =SUMIFS(RESUMEN_MES!$Y$6:$Y$29,RESUMEN_MES!$A$6:$A$29,">="&$C$4,RESUMEN_MES!$A$6:$A$29,"<="&$C$5) -> -113.5385 | K24: =IF(I24=0,0,J24/I24) -> -0.012559568
B25: Distribución Centro | C25: =SUMIFS(CALCULO!$AS$6:$AS$305,CALCULO!$D$6:$D$305,">="&$C$4,CALCULO!$D$6:$D$305,"<="&$C$5) -> 3395 | D25: =IF($C$10=0,0,C25/$C$10) -> 0.10533664 | E25: =IF($C$9=0,0,C25/$C$9) -> 0.084663342 | G25: Fijos no absorbidos | J25: =SUMIFS(RESUMEN_MES!$Z$6:$Z$29,RESUMEN_MES!$A$6:$A$29,">="&$C$4,RESUMEN_MES!$A$6:$A$29,"<="&$C$5) -> 0
B26: Distribución Oriente | C26: =SUMIFS(CALCULO!$BC$6:$BC$305,CALCULO!$D$6:$D$305,">="&$C$4,CALCULO!$D$6:$D$305,"<="&$C$5) -> 5485 | D26: =IF($C$10=0,0,C26/$C$10) -> 0.17018306 | E26: =IF($C$9=0,0,C26/$C$9) -> 0.13678304 | G26: TOTAL | H26: =SUM(H22:H24) -> 40100 | I26: =SUM(I22:I24) -> 32080 | J26: =SUM(J22:J25) -> 9168.3167 | K26: =IF(I26=0,0,J26/I26) -> 0.28579541
B27: Comercialización variable | C27: =SUMIFS(CALCULO!$BH$6:$BH$305,CALCULO!$D$6:$D$305,">="&$C$4,CALCULO!$D$6:$D$305,"<="&$C$5) -> 962.4 | D27: =IF($C$10=0,0,C27/$C$10) -> 0.029860379 | E27: =IF($C$9=0,0,C27/$C$9) -> 0.024 | G27: Los ingresos regionales no incluyen «otros ingresos», que se reparten en la utilidad según los kg.
B28: Reclamaciones y banca | C28: =SUMIFS(CALCULO!$BI$6:$BI$305,CALCULO!$D$6:$D$305,">="&$C$4,CALCULO!$D$6:$D$305,"<="&$C$5)+SUMIFS(CALCULO!$BJ$6:$BJ$305,CALCULO!$D$6:$D$305,">="&$C$4,CALCULO!$D$6:$D$305,"<="&$C$5) -> 483.45 | D28: =IF($C$10=0,0,C28/$C$10) -> 0.015 | E28: =IF($C$9=0,0,C28/$C$9) -> 0.01205611
B29: Otros gastos directos | C29: =SUMIFS(CALCULO!$BK$6:$BK$305,CALCULO!$D$6:$D$305,">="&$C$4,CALCULO!$D$6:$D$305,"<="&$C$5) -> 35 | D29: =IF($C$10=0,0,C29/$C$10) -> 0.0010859448 | E29: =IF($C$9=0,0,C29/$C$9) -> 0.00087281796
B30: Costos fijos | C30: =SUMIFS(RESUMEN_MES!$K$6:$K$29,RESUMEN_MES!$A$6:$A$29,">="&$C$4,RESUMEN_MES!$A$6:$A$29,"<="&$C$5) -> 6480.1333 | D30: =IF($C$10=0,0,C30/$C$10) -> 0.20105905 | E30: =IF($C$9=0,0,C30/$C$9) -> 0.16159933
B31: Tributos sobre ingresos | C31: =SUMIFS(RESUMEN_MES!$N$6:$N$29,RESUMEN_MES!$A$6:$A$29,">="&$C$4,RESUMEN_MES!$A$6:$A$29,"<="&$C$5) -> 3545.3 | D31: =IF($C$10=0,0,C31/$C$10) -> 0.11 | E31: =IF($C$9=0,0,C31/$C$9) -> 0.088411471
B32: TOTAL COSTOS | C32: =SUM(C22:C31) -> 23061.683 | D32: =IF($C$10=0,0,C32/$C$10) -> 0.7155347 | E32: =IF($C$9=0,0,C32/$C$9) -> 0.57510432
B33: Control: ingresos − costos − utilidad (debe ser 0) | C33: =ROUND(C10-C32-C16,2) -> 0
B35: Evolución mensual del período (máx. 12 meses)
B36: Mes | C36: Ingresos | D36: Costos totales | E36: Utilidad antes de impuesto
B37: =IF(EDATE($C$4,0)>$C$5,"",EDATE($C$4,0)) -> 46266 | C37: =IF($B37="","",SUMIFS(RESUMEN_MES!$G$6:$G$29,RESUMEN_MES!$A$6:$A$29,$B37)) -> 15600 | D37: =IF($B37="","",SUMIFS(RESUMEN_MES!$AB$6:$AB$29,RESUMEN_MES!$A$6:$A$29,$B37)) -> 11530.267 | E37: =IF($B37="","",SUMIFS(RESUMEN_MES!$O$6:$O$29,RESUMEN_MES!$A$6:$A$29,$B37)) -> 4069.7333
B38: =IF(EDATE($C$4,1)>$C$5,"",EDATE($C$4,1)) -> 46296 | C38: =IF($B38="","",SUMIFS(RESUMEN_MES!$G$6:$G$29,RESUMEN_MES!$A$6:$A$29,$B38)) -> 16630 | D38: =IF($B38="","",SUMIFS(RESUMEN_MES!$AB$6:$AB$29,RESUMEN_MES!$A$6:$A$29,$B38)) -> 11531.417 | E38: =IF($B38="","",SUMIFS(RESUMEN_MES!$O$6:$O$29,RESUMEN_MES!$A$6:$A$29,$B38)) -> 5098.5833
B39: =IF(EDATE($C$4,2)>$C$5,"",EDATE($C$4,2)) | C39: =IF($B39="","",SUMIFS(RESUMEN_MES!$G$6:$G$29,RESUMEN_MES!$A$6:$A$29,$B39)) | D39: =IF($B39="","",SUMIFS(RESUMEN_MES!$AB$6:$AB$29,RESUMEN_MES!$A$6:$A$29,$B39)) | E39: =IF($B39="","",SUMIFS(RESUMEN_MES!$O$6:$O$29,RESUMEN_MES!$A$6:$A$29,$B39))
B40: =IF(EDATE($C$4,3)>$C$5,"",EDATE($C$4,3)) | C40: =IF($B40="","",SUMIFS(RESUMEN_MES!$G$6:$G$29,RESUMEN_MES!$A$6:$A$29,$B40)) | D40: =IF($B40="","",SUMIFS(RESUMEN_MES!$AB$6:$AB$29,RESUMEN_MES!$A$6:$A$29,$B40)) | E40: =IF($B40="","",SUMIFS(RESUMEN_MES!$O$6:$O$29,RESUMEN_MES!$A$6:$A$29,$B40))
B41: =IF(EDATE($C$4,4)>$C$5,"",EDATE($C$4,4)) | C41: =IF($B41="","",SUMIFS(RESUMEN_MES!$G$6:$G$29,RESUMEN_MES!$A$6:$A$29,$B41)) | D41: =IF($B41="","",SUMIFS(RESUMEN_MES!$AB$6:$AB$29,RESUMEN_MES!$A$6:$A$29,$B41)) | E41: =IF($B41="","",SUMIFS(RESUMEN_MES!$O$6:$O$29,RESUMEN_MES!$A$6:$A$29,$B41))
B42: =IF(EDATE($C$4,5)>$C$5,"",EDATE($C$4,5)) | C42: =IF($B42="","",SUMIFS(RESUMEN_MES!$G$6:$G$29,RESUMEN_MES!$A$6:$A$29,$B42)) | D42: =IF($B42="","",SUMIFS(RESUMEN_MES!$AB$6:$AB$29,RESUMEN_MES!$A$6:$A$29,$B42)) | E42: =IF($B42="","",SUMIFS(RESUMEN_MES!$O$6:$O$29,RESUMEN_MES!$A$6:$A$29,$B42))
B43: =IF(EDATE($C$4,6)>$C$5,"",EDATE($C$4,6)) | C43: =IF($B43="","",SUMIFS(RESUMEN_MES!$G$6:$G$29,RESUMEN_MES!$A$6:$A$29,$B43)) | D43: =IF($B43="","",SUMIFS(RESUMEN_MES!$AB$6:$AB$29,RESUMEN_MES!$A$6:$A$29,$B43)) | E43: =IF($B43="","",SUMIFS(RESUMEN_MES!$O$6:$O$29,RESUMEN_MES!$A$6:$A$29,$B43))
B44: =IF(EDATE($C$4,7)>$C$5,"",EDATE($C$4,7)) | C44: =IF($B44="","",SUMIFS(RESUMEN_MES!$G$6:$G$29,RESUMEN_MES!$A$6:$A$29,$B44)) | D44: =IF($B44="","",SUMIFS(RESUMEN_MES!$AB$6:$AB$29,RESUMEN_MES!$A$6:$A$29,$B44)) | E44: =IF($B44="","",SUMIFS(RESUMEN_MES!$O$6:$O$29,RESUMEN_MES!$A$6:$A$29,$B44))
...

Sheet ENTRADA
A1: Registro de contenedores (ENTRADA DE DATOS)
A2: Una fila por contenedor. Columnas «(opcional)»: si se dejan vacías se usa la norma técnica de PARAMETROS. Para borrar datos use la tecla Supr; nunca elimine filas.
A4: IDENTIFICACIÓN | G4: VOLUMEN (kg) | J4: ETAPA 1 · PUERTO | M4: ETAPA 2 · TRANSITARIA | O4: ETAPA 3 · DISTRIBUCIÓN | V4: OTROS | Y4: CONTROL | AB4: RESULTADO
A5: Nº | B5: ID contenedor | C5: Fecha de arribo | D5: Transitaria | E5: Tipo | F5: Nº de bultos | G5: kg Occidente | H5: kg Centro | I5: kg Oriente | J5: Viajes al puerto (opcional) | K5: Litros reales al puerto (opcional) | L5: Dieta pagada (USD, opcional) | M5: Jornales del desagrupe (opcional) | N5: Estadía / almacenaje / demora (USD) | O5: Litros de distribución en Occidente (opcional) | P5: Litros de traslado a Centro (opcional) | Q5: Litros de distribución en Centro (opcional) | R5: Jornales del centro transitorio en Centro (opcional) | S5: Litros de traslado a Oriente (opcional) | T5: Litros de distribución en Oriente (opcional) | U5: Jornales del centro transitorio en Oriente (opcional) | V5: Otros gastos directos (USD) | W5: Detalle de otros gastos | X5: Otros ingresos (USD) | Y5: Fecha de fin de la distribución | Z5: Estado | AA5: Observaciones / documentos de soporte | AB5: Alertas (automático) | AC5: Utilidad antes de impuesto (automático)
A6: =IF(B6="","",ROW()-5) -> 1 | B6: CONT-EJEMPLO-01 | C6: 46273 | D6: ENCI | E6: 40' HC | F6: 1050 | G6: 5200 | H6: 2600 | I6: 2300 | K6: 62 | M6: 11 | N6: 0 | V6: 0 | X6: 0 | Y6: 46283 | Z6: Cerrado | AA6: EJEMPLO – borrar | AB6: =CALCULO!CT6 | AC6: =CALCULO!CD6 -> 2175.8201
A7: =IF(B7="","",ROW()-5) -> 2 | B7: CONT-EJEMPLO-02 | C7: 46287 | D7: A.V | E7: 40' | F7: 900 | G7: 4600 | H7: 2100 | I7: 2700 | N7: 120 | S7: 480 | V7: 0 | X7: 0 | Y7: 46298 | Z7: Cerrado | AA7: EJEMPLO – 2 días de estadía | AB7: =CALCULO!CT7 | AC7: =CALCULO!CD7 -> 1893.9132
A8: =IF(B8="","",ROW()-5) -> 3 | B8: CONT-EJEMPLO-03 | C8: 46301 | D8: ENCI | E8: 40' HC | F8: 1180 | G8: 6100 | H8: 2900 | I8: 2400 | N8: 0 | O8: 150 | T8: 260 | V8: 35 | W8: Reempaque de bultos dañados | X8: 150 | Y8: 46311 | Z8: Cerrado | AA8: EJEMPLO – desvío de combustible en Oriente | AB8: =CALCULO!CT8 -> Combustible distribución Oriente +44% sobre norma. | AC8: =CALCULO!CD8 -> 3043.8013
A9: =IF(B9="","",ROW()-5) -> 4 | B9: CONT-EJEMPLO-04 | C9: 46315 | D9: A.V | E9: 40' | F9: 860 | G9: 3800 | H9: 1500 | I9: 3900 | N9: 0 | V9: 0 | X9: 0 | Z9: Abierto | AA9: EJEMPLO – pendiente de datos reales | AB9: =CALCULO!CT9 | AC9: =CALCULO!CD9 -> 2054.7821
A10: =IF(B10="","",ROW()-5) | AB10: =CALCULO!CT10 | AC10: =CALCULO!CD10
A11: =IF(B11="","",ROW()-5) | AB11: =CALCULO!CT11 | AC11: =CALCULO!CD11
A12: =IF(B12="","",ROW()-5) | AB12: =CALCULO!CT12 | AC12: =CALCULO!CD12
A13: =IF(B13="","",ROW()-5) | AB13: =CALCULO!CT13 | AC13: =CALCULO!CD13
A14: =IF(B14="","",ROW()-5) | AB14: =CALCULO!CT14 | AC14: =CALCULO!CD14
A15: =IF(B15="","",ROW()-5) | AB15: =CALCULO!CT15 | AC15: =CALCULO!CD15
A16: =IF(B16="","",ROW()-5) | AB16: =CALCULO!CT16 | AC16: =CALCULO!CD16
A17: =IF(B17="","",ROW()-5) | AB17: =CALCULO!CT17 | AC17: =CALCULO!CD17
A18: =IF(B18="","",ROW()-5) | AB18: =CALCULO!CT18 | AC18: =CALCULO!CD18
A19: =IF(B19="","",ROW()-5) | AB19: =CALCULO!CT19 | AC19: =CALCULO!CD19
A20: =IF(B20="","",ROW()-5) | AB20: =CALCULO!CT20 | AC20: =CALCULO!CD20
A21: =IF(B21="","",ROW()-5) | AB21: =CALCULO!CT21 | AC21: =CALCULO!CD21
... A305: =IF(B305="","",ROW()-5) | AB305: =CALCULO!CT305 | AC305: =CALCULO!CD305

Sheet PARAMETROS
A1: Parámetros generales, normas técnicas y tributos
A2: Valores estables del modelo. Los precios que cambian con el tiempo van en la hoja PRECIOS (con fecha de vigencia).
A4: Nombre (referencia) | B4: Concepto | C4: Valor | D4: Unidad | E4: Fuente / nota
A5: A. GENERALES
A6: Empresa | B6: Nombre de la empresa | C6: Empresa de Paquetería (editar) | D6: texto | E6: Aparece en los encabezados.
A7: Fecha_Inicio | B7: Primer mes del período de análisis | C7: 46266 | D7: fecha | E7: Primer mes que se registra. COSTOS_FIJOS y RESUMEN_MES abarcan 24 meses desde esta fecha.
A8: Metodo_Prorrateo | B8: Base de reparto de los costos fijos entre contenedores | C8: KG | D8: lista | E8: KG = proporcional al peso (recomendado: un contenedor más cargado absorbe más estructura). CONTENEDOR = partes iguales.
A9: Base_Comision | B9: Base del pago variable de comercialización | C9: % DEL INGRESO | D9: lista | E9: % DEL INGRESO: tasa sobre lo cobrado. USD POR KG: importe por kg entregado. Las tasas están en PRECIOS.
A10: Tolerancia_Comb | B10: Tolerancia del desvío de combustible frente a la norma | C10: 0.1 | D10: % | E10: Si el consumo real supera la norma en más de este %, se genera una alerta.
A11: Mes_Corte | B11: Último mes incluido en los resultados (opcional) | D11: fecha | E11: Vacío = último mes con contenedores registrados. Los meses posteriores no cargan costos fijos en RESUMEN_MES ni en DASHBOARD.
A12: B. NORMAS TÉCNICAS (se usan cuando no hay dato real)
A13: Std_Viajes_Puerto | B13: Viajes al puerto por contenedor | C13: 1 | D13: viajes | E13: Un contenedor = un viaje del camión propio.
A14: Litros_Puerto_Viaje | B14: Combustible por viaje al puerto | C14: 60 | D14: L / viaje | E14: Dato informado por la empresa.
A15: Km_Puerto_Viaje | B15: Km por viaje al puerto (ida y vuelta) | C15: 180 | D15: km / viaje | E15: ILUSTRATIVO: sustituir por el dato real. Medir con la hoja de ruta.
A16: Rend_Desagrupe | B16: Rendimiento del desagrupe en la transitaria | C16: 1000 | D16: kg / jornal | E16: ILUSTRATIVO: sustituir por el dato real. Jornales = kg ÷ rendimiento (redondeado hacia arriba).
A17: Rend_Desagrupe_CT | B17: Rendimiento del desagrupe en los centros transitorios (Centro y Oriente) | C17: 800 | D17: kg / jornal | E17: ILUSTRATIVO: sustituir por el dato real.
A18: Cap_Camion_OCC | B18: Capacidad útil del camión de distribución – Occidente | C18: 5000 | D18: kg / viaje | E18: ILUSTRATIVO: sustituir por el dato real. Viajes = kg ÷ capacidad (redondeado hacia arriba).
A19: Cap_Camion_CEN | B19: Capacidad útil del camión de traslado – Centro | C19: 5000 | D19: kg / viaje | E19: ILUSTRATIVO: sustituir por el dato real.
A20: Cap_Camion_ORI | B20: Capacidad útil del camión de traslado – Oriente | C20: 5000 | D20: kg / viaje | E20: ILUSTRATIVO: sustituir por el dato real.
A21: L_Dist_OCC | B21: Combustible de distribución en Occidente | C21: 120 | D21: L / viaje | E21: ILUSTRATIVO: sustituir por el dato real.
A22: L_Tras_CEN | B22: Combustible de traslado al centro transitorio – Centro | C22: 250 | D22: L / viaje | E22: ILUSTRATIVO: sustituir por el dato real.
A23: L_Dist_CEN | B23: Combustible de distribución en Centro | C23: 150 | D23: L / viaje | E23: ILUSTRATIVO: sustituir por el dato real.
A24: L_Tras_ORI | B24: Combustible de traslado al centro transitorio – Oriente | C24: 450 | D24: L / viaje | E24: ILUSTRATIVO: sustituir por el dato real.
A25: L_Dist_ORI | B25: Combustible de distribución en Oriente | C25: 180 | D25: L / viaje | E25: ILUSTRATIVO: sustituir por el dato real.
A26: C. OTROS COSTOS VARIABLES (sobre el ingreso)
A27: Pct_Reclamaciones | B27: Provisión para pérdidas, daños y reclamaciones | C27: 0.005 | D27: % ingreso | E27: Recomendado. ILUSTRATIVO: sustituir por el dato real. Use 0 si no aplica.
A28: Pct_Banco | B28: Comisiones bancarias y costo de cobro | C28: 0.01 | D28: % ingreso | E28: Recomendado. ILUSTRATIVO: sustituir por el dato real. Use 0 si no aplica.
A29: D. TRIBUTOS (régimen general MIPYME – confirmar con el contador / ONAT)
A30: Imp_Ventas_Serv | B30: Impuesto sobre las ventas y los servicios | C30: 0.1 | D30: % ingreso | E30: Ley 113 del Sistema Tributario; vigente en 2026 según la Ley del Presupuesto.
A31: Contrib_Territorial | B31: Contribución territorial para el desarrollo local | C31: 0.01 | D31: % ingreso | E31: Ley 113; vigente en 2026.
A32: Contrib_SS | B32: Contribución a la seguridad social (empleador) | C32: 0.14 | D32: % salarios | E32: Solo sobre salarios de trabajadores propios.
A33: Imp_Fuerza_Trabajo | B33: Impuesto por la utilización de la fuerza de trabajo | C33: 0.05 | D33: % salarios | E33: Solo sobre salarios de trabajadores propios. Confirmar si la empresa tiene alguna bonificación.
A34: Imp_Utilidades | B34: Impuesto sobre las utilidades | C34: 0.35 | D34: % utilidad | E34: Liquidación anual con pagos a cuenta. En el libro es una estimación.

Sheet PRECIOS
A1: Precios y tarifas con fecha de vigencia
A2: Cuando cambie un precio, AGREGUE una fila nueva con la fecha desde la que rige (en orden ascendente). No sobrescriba las anteriores: cada contenedor usa los precios vigentes en su fecha de arribo.
A5: Vigente desde | B5: Tarifa Occidente (USD/kg) | C5: Tarifa Centro (USD/kg) | D5: Tarifa Oriente (USD/kg) | E5: Precio diésel (USD/L) | F5: Cita del puerto (USD/viaje) | G5: Dieta del chofer (USD/viaje) | H5: Pago por jornal – transitaria (USD) | I5: Pago por jornal – centro transitorio (USD) | J5: Servicio ENCI (USD/contenedor) | K5: Servicio A.V (USD/contenedor) | L5: Comisión variable (% del ingreso) | M5: Comisión variable (USD/kg) | N5: Desgaste del vehículo propio (USD/km) | O5: Documento de soporte / nota
A6: 46023 | B6: 0.8 | C6: 0.8 | D6: 0.8 | E6: 2 | F6: 10 | G6: 10 | H6: 15 | I6: 15 | J6: 0 | K6: 0 | L6: 0.03 | M6: 0.03 | N6: 0.12 | O6: EJEMPLO. Cita 10 USD = dato de la empresa. Diésel 2,00 USD/L = referencia de CUPET 2026. Resto ILUSTRATIVO: sustituir.

Sheet ACTIVOS
A1: Activos fijos: depreciación, mantenimiento y seguros
A2: Método lineal. La depreciación se calcula desde el mes de alta hasta el fin de la vida útil o la fecha de baja. Confirme las tasas con la norma contable vigente.
A5: Nº | B5: Descripción / chapa | C5: Tipo | D5: Fecha de alta | E5: Valor de adquisición (USD) | F5: Valor residual (USD) | G5: Vida útil (años) | H5: Depreciación anual (USD) | I5: Depreciación mensual (USD) | J5: Fin de la depreciación | K5: Fecha de baja (si se vendió o retiró) | L5: Mantenimiento preventivo (USD/mes) | M5: Seguros, licencias e inspecciones (USD/año) | N5: Seguros y licencias (USD/mes) | O5: Observaciones
A6: 1 | B6: Camión porta-contenedor (recogida en el puerto) – EJEMPLO | C6: Vehículo propio | D6: 45658 | E6: 45000 | F6: 5000 | G6: 8 | H6: =IF(OR(D6="",N(G6)=0),0,(E6-F6)/G6) -> 5000 | I6: =H6/12 -> 416.66667 | J6: =IF(OR(D6="",N(G6)=0),0,EDATE(D6,G6*12)) -> 48580 | L6: 150 | M6: 1020 | N6: =N(M6)/12 -> 85 | O6: ILUSTRATIVO: sustituir por el valor contable real.
A7: 2 | B7: Computadoras y equipos de oficina – EJEMPLO | C7: Equipo | D7: 46023 | E7: 1500 | F7: 0 | G7: 5 | H7: =IF(OR(D7="",N(G7)=0),0,(E7-F7)/G7) -> 300 | I7: =H7/12 -> 25 | J7: =IF(OR(D7="",N(G7)=0),0,EDATE(D7,G7*12)) -> 47849 | L7: 0 | M7: 0 | N7: =N(M7)/12 -> 0 | O7: ILUSTRATIVO
A8: 3 | H8: =IF(OR(D8="",N(G8)=0),0,(E8-F8)/G8) -> 0 | I8: =H8/12 -> 0 | J8: =IF(OR(D8="",N(G8)=0),0,EDATE(D8,G8*12)) -> 00:00:00 | N8: =N(M8)/12 -> 0
A9: 4 | H9: =IF(OR(D9="",N(G9)=0),0,(E9-F9)/G9) -> 0 | I9: =H9/12 -> 0 | J9: =IF(OR(D9="",N(G9)=0),0,EDATE(D9,G9*12)) -> 00:00:00 | N9: =N(M9)/12 -> 0
A10: 5 | H10: =IF(OR(D10="",N(G10)=0),0,(E10-F10)/G10) -> 0 | I10: =H10/12 -> 0 | J10: =IF(OR(D10="",N(G10)=0),0,EDATE(D10,G10*12)) -> 00:00:00 | N10: =N(M10)/12 -> 0
A11: 6 | H11: =IF(OR(D11="",N(G11)=0),0,(E11-F11)/G11) -> 0 | I11: =H11/12 -> 0 | J11: =IF(OR(D11="",N(G11)=0),0,EDATE(D11,G11*12)) -> 00:00:00 | N11: =N(M11)/12 -> 0
A12: 7 | H12: =IF(OR(D12="",N(G12)=0),0,(E12-F12)/G12) -> 0 | I12: =H12/12 -> 0 | J12: =IF(OR(D12="",N(G12)=0),0,EDATE(D12,G12*12)) -> 00:00:00 | N12: =N(M12)/12 -> 0
A13: 8 | H13: =IF(OR(D13="",N(G13)=0),0,(E13-F13)/G13) -> 0 | I13: =H13/12 -> 0 | J13: =IF(OR(D13="",N(G13)=0),0,EDATE(D13,G13*12)) -> 00:00:00 | N13: =N(M13)/12 -> 0
A14: 9 | H14: =IF(OR(D14="",N(G14)=0),0,(E14-F14)/G14) -> 0 | I14: =H14/12 -> 0 | J14: =IF(OR(D14="",N(G14)=0),0,EDATE(D14,G14*12)) -> 00:00:00 | N14: =N(M14)/12 -> 0
A15: 10 | H15: =IF(OR(D15="",N(G15)=0),0,(E15-F15)/G15) -> 0 | I15: =H15/12 -> 0 | J15: =IF(OR(D15="",N(G15)=0),0,EDATE(D15,G15*12)) -> 00:00:00 | N15: =N(M15)/12 -> 0
B16: TOTAL | E16: =SUM(E6:E15) -> 46500 | F16: =SUM(F6:F15) -> 5000 | H16: =SUM(H6:H15) -> 5300 | I16: =SUM(I6:I15) -> 441.66667 | L16: =SUM(L6:L15) -> 150 | N16: =SUM(N6:N15) -> 85

Sheet COSTOS_FIJOS
A1: Costos fijos mensuales por centro de costo
A2: La columna «Valor base» se copia a cada mes. Si el gasto real de un mes fue distinto, escriba el valor real en la celda de ese mes. Las filas en negro se calculan solas.
A5: Código | B5: Concepto | C5: Centro de costo | D5: Elemento de gasto | E5: ¿Salario de trabajador propio? | F5: Valor base mensual (USD) | G5: =EDATE(Fecha_Inicio,0) -> 46266 | H5: =EDATE(Fecha_Inicio,1) -> 46296 | I5: =EDATE(Fecha_Inicio,2) -> 46327 | J5: =EDATE(Fecha_Inicio,3) -> 46357 | K5: =EDATE(Fecha_Inicio,4) -> 46388 | L5: =EDATE(Fecha_Inicio,5) -> 46419 | M5: =EDATE(Fecha_Inicio,6) -> 46447 | N5: =EDATE(Fecha_Inicio,7) -> 46478 | O5: =EDATE(Fecha_Inicio,8) -> 46508 | P5: =EDATE(Fecha_Inicio,9) -> 46539 | Q5: =EDATE(Fecha_Inicio,10) -> 46569 | R5: =EDATE(Fecha_Inicio,11) -> 46600 | S5: =EDATE(Fecha_Inicio,12) -> 46631 | T5: =EDATE(Fecha_Inicio,13) -> 46661 | U5: =EDATE(Fecha_Inicio,14) -> 46692 | V5: =EDATE(Fecha_Inicio,15) -> 46722 | W5: =EDATE(Fecha_Inicio,16) -> 46753 | X5: =EDATE(Fecha_Inicio,17) -> 46784 | Y5: =EDATE(Fecha_Inicio,18) -> 46813 | Z5: =EDATE(Fecha_Inicio,19) -> 46844 | AA5: =EDATE(Fecha_Inicio,20) -> 46874 | AB5: =EDATE(Fecha_Inicio,21) -> 46905 | AC5: =EDATE(Fecha_Inicio,22) -> 46935 | AD5: =EDATE(Fecha_Inicio,23) -> 46966 | AE5: Total período
A6: CF01 | B6: Salario del chofer del vehículo propio (puerto) | C6: GENERAL | D6: Gastos de fuerza de trabajo | E6: Sí | F6: 60 | G6: =$F6 -> 60 | H6: =$F6 -> 60 | I6: =$F6 -> 60 | J6: =$F6 -> 60 | K6: =$F6 -> 60 | L6: =$F6 -> 60 | M6: =$F6 -> 60 | N6: =$F6 -> 60 | ... AD6: =$F6 -> 60 | AE6: =SUM(G6:AD6) -> 1440
A7: CF02 | B7: Salarios de dirección, economía y contabilidad | C7: GENERAL | D7: Gastos de fuerza de trabajo | E7: Sí | F7: 250 | G7: =$F7 -> 250 | H7: =$F7 -> 250 | I7: =$F7 -> 250 | J7: =$F7 -> 250 | K7: =$F7 -> 250 | L7: =$F7 -> 250 | M7: =$F7 -> 250 | N7: =$F7 -> 250 | ... AD7: =$F7 -> 250 | AE7: =SUM(G7:AD7) -> 6000
A8: CF03 | B8: Comercialización – parte fija (21 gestores, desde COMERCIAL) | C8: GENERAL | D8: Gastos de fuerza de trabajo | E8: Sí | F8: =COMERCIAL!F33 -> 1050 | G8: =$F8 -> 1050 | H8: =$F8 -> 1050 | I8: =$F8 -> 1050 | J8: =$F8 -> 1050 | K8: =$F8 -> 1050 | L8: =$F8 -> 1050 | M8: =$F8 -> 1050 | N8: =$F8 -> 1050 | ... AD8: =$F8 -> 1050 | AE8: =SUM(G8:AD8) -> 25200
A9: CF04 | B9: Alquiler de local / almacén | C9: GENERAL | D9: Otros gastos monetarios | E9: No | F9: 200 | G9: =$F9 -> 200 | H9: =$F9 -> 200 | I9: =$F9 -> 200 | J9: =$F9 -> 200 | K9: =$F9 -> 200 | L9: =$F9 -> 200 | M9: =$F9 -> 200 | N9: =$F9 -> 200 | ... AD9: =$F9 -> 200 | AE9: =SUM(G9:AD9) -> 4800
A10: CF05 | B10: Electricidad y agua | C10: GENERAL | D10: Energía | E10: No | F10: 40 | G10: =$F10 -> 40 | H10: =$F10 -> 40 | I10: =$F10 -> 40 | J10: =$F10 -> 40 | K10: =$F10 -> 40 | L10: =$F10 -> 40 | M10: =$F10 -> 40 | N10: =$F10 -> 40 | ... AD10: =$F10 -> 40 | AE10: =SUM(G10:AD10) -> 960
A11: CF06 | B11: Comunicaciones (teléfono, internet) | C11: GENERAL | D11: Otros gastos monetarios | E11: No | F11: 30 | G11: =$F11 -> 30 | H11: =$F11 -> 30 | I11: =$F11 -> 30 | J11: =$F11 -> 30 | K11: =$F11 -> 30 | L11: =$F11 -> 30 | M11: =$F11 -> 30 | N11: =$F11 -> 30 | ... AD11: =$F11 -> 30 | AE11: =SUM(G11:AD11) -> 720
A12: CF07 | B12: Materiales de oficina y limpieza | C12: GENERAL | D12: Materias primas y materiales | E12: No | F12: 15 | G12: =$F12 -> 15 | H12: =$F12 -> 15 | I12: =$F12 -> 15 | J12: =$F12 -> 15 | K12: =$F12 -> 15 | L12: =$F12 -> 15 | M12: =$F12 -> 15 | N12: =$F12 -> 15 | ... AD12: =$F12 -> 15 | AE12: =SUM(G12:AD12) -> 360
A13: CF08 | B13: Servicios contables, legales y otros externos | C13: GENERAL | D13: Otros gastos monetarios | E13: No | F13: 50 | G13: =$F13 -> 50 | H13: =$F13 -> 50 | I13: =$F13 -> 50 | J13: =$F13 -> 50 | K13: =$F13 -> 50 | L13: =$F13 -> 50 | M13: =$F13 -> 50 | N13: =$F13 -> 50 | ... AD13: =$F13 -> 50 | AE13: =SUM(G13:AD13) -> 1200
A14: CF09 | B14: Gastos bancarios fijos (mantenimiento de cuenta) | C14: GENERAL | D14: Otros gastos monetarios | E14: No | F14: 10 | G14: =$F14 -> 10 | H14: =$F14 -> 10 | I14: =$F14 -> 10 | J14: =$F14 -> 10 | K14: =$F14 -> 10 | L14: =$F14 -> 10 | M14: =$F14 -> 10 | N14: =$F14 -> 10 | ... AD14: =$F14 -> 10 | AE14: =SUM(G14:AD14) -> 240
A15: CF10 | B15: Depreciación de activos fijos (desde ACTIVOS) | C15: GENERAL | D15: Depreciación y amortización | E15: No | F15: =ACTIVOS!I16 -> 441.66667 | G15: =SUMPRODUCT((ACTIVOS!$D$6:$D$15>0)*(ACTIVOS!$D$6:$D$15<=EOMONTH(G$5,0))*(((ACTIVOS!$K$6:$K$15=0)+(ACTIVOS!$K$6:$K$15>G$5))>0)*(ACTIVOS!$J$6:$J$15>G$5)*ACTIVOS!$I$6:$I$15) -> 441.66667 | H15: =SUMPRODUCT((ACTIVOS!$D$6:$D$15>0)*(ACTIVOS!$D$6:$D$15<=EOMONTH(H$5,0))*(((ACTIVOS!$K$6:$K$15=0)+(ACTIVOS!$K$6:$K$15>H$5))>0)*(ACTIVOS!$J$6:$J$15>H$5)*ACTIVOS!$I$6:$I$15) -> 441.66667 | I15: =SUMPRODUCT((ACTIVOS!$D$6:$D$15>0)*(ACTIVOS!$D$6:$D$15<=EOMONTH(I$5,0))*(((ACTIVOS!$K$6:$K$15=0)+(ACTIVOS!$K$6:$K$15>I$5))>0)*(ACTIVOS!$J$6:$J$15>I$5)*ACTIVOS!$I$6:$I$15) -> 441.66667 | J15: =SUMPRODUCT((ACTIVOS!$D$6:$D$15>0)*(ACTIVOS!$D$6:$D$15<=EOMONTH(J$5,0))*(((ACTIVOS!$K$6:$K$15=0)+(ACTIVOS!$K$6:$K$15>J$5))>0)*(ACTIVOS!$J$6:$J$15>J$5)*ACTIVOS!$I$6:$I$15) -> 441.66667 | K15: =SUMPRODUCT((ACTIVOS!$D$6:$D$15>0)*(ACTIVOS!$D$6:$D$15<=EOMONTH(K$5,0))*(((ACTIVOS!$K$6:$K$15=0)+(ACTIVOS!$K$6:$K$15>K$5))>0)*(ACTIVOS!$J$6:$J$15>K$5)*ACTIVOS!$I$6:$I$15) -> 441.66667 | L15: =SUMPRODUCT((ACTIVOS!$D$6:$D$15>0)*(ACTIVOS!$D$6:$D$15<=EOMONTH(L$5,0))*(((ACTIVOS!$K$6:$K$15=0)+(ACTIVOS!$K$6:$K$15>L$5))>0)*(ACTIVOS!$J$6:$J$15>L$5)*ACTIVOS!$I$6:$I$15) -> 441.66667 | M15: =SUMPRODUCT((ACTIVOS!$D$6:$D$15>0)*(ACTIVOS!$D$6:$D$15<=EOMONTH(M$5,0))*(((ACTIVOS!$K$6:$K$15=0)+(ACTIVOS!$K$6:$K$15>M$5))>0)*(ACTIVOS!$J$6:$J$15>M$5)*ACTIVOS!$I$6:$I$15) -> 441.66667 | N15: =SUMPRODUCT((ACTIVOS!$D$6:$D$15>0)*(ACTIVOS!$D$6:$D$15<=EOMONTH(N$5,0))*(((ACTIVOS!$K$6:$K$15=0)+(ACTIVOS!$K$6:$K$15>N$5))>0)*(ACTIVOS!$J$6:$J$15>N$5)*ACTIVOS!$I$6:$I$15) -> 441.66667 | ... AD15: =SUMPRODUCT((ACTIVOS!$D$6:$D$15>0)*(ACTIVOS!$D$6:$D$15<=EOMONTH(AD$5,0))*(((ACTIVOS!$K$6:$K$15=0)+(ACTIVOS!$K$6:$K$15>AD$5))>0)*(ACTIVOS!$J$6:$J$15>AD$5)*ACTIVOS!$I$6:$I$15) -> 441.66667 | AE15: =SUM(G15:AD15) -> 10600
A16: CF11 | B16: Mantenimiento preventivo de la flota propia (desde ACTIVOS) | C16: GENERAL | D16: Materias primas y materiales | E16: No | F16: =ACTIVOS!L16 -> 150 | G16: =SUMPRODUCT((ACTIVOS!$D$6:$D$15>0)*(ACTIVOS!$D$6:$D$15<=EOMONTH(G$5,0))*(((ACTIVOS!$K$6:$K$15=0)+(ACTIVOS!$K$6:$K$15>G$5))>0)*ACTIVOS!$L$6:$L$15) -> 150 | H16: =SUMPRODUCT((ACTIVOS!$D$6:$D$15>0)*(ACTIVOS!$D$6:$D$15<=EOMONTH(H$5,0))*(((ACTIVOS!$K$6:$K$15=0)+(ACTIVOS!$K$6:$K$15>H$5))>0)*ACTIVOS!$L$6:$L$15) -> 150 | I16: =SUMPRODUCT((ACTIVOS!$D$6:$D$15>0)*(ACTIVOS!$D$6:$D$15<=EOMONTH(I$5,0))*(((ACTIVOS!$K$6:$K$15=0)+(ACTIVOS!$K$6:$K$15>I$5))>0)*ACTIVOS!$L$6:$L$15) -> 150 | J16: =SUMPRODUCT((ACTIVOS!$D$6:$D$15>0)*(ACTIVOS!$D$6:$D$15<=EOMONTH(J$5,0))*(((ACTIVOS!$K$6:$K$15=0)+(ACTIVOS!$K$6:$K$15>J$5))>0)*ACTIVOS!$L$6:$L$15) -> 150 | K16: =SUMPRODUCT((ACTIVOS!$D$6:$D$15>0)*(ACTIVOS!$D$6:$D$15<=EOMONTH(K$5,0))*(((ACTIVOS!$K$6:$K$15=0)+(ACTIVOS!$K$6:$K$15>K$5))>0)*ACTIVOS!$L$6:$L$15) -> 150 | L16: =SUMPRODUCT((ACTIVOS!$D$6:$D$15>0)*(ACTIVOS!$D$6:$D$15<=EOMONTH(L$5,0))*(((ACTIVOS!$K$6:$K$15=0)+(ACTIVOS!$K$6:$K$15>L$5))>0)*ACTIVOS!$L$6:$L$15) -> 150 | M16: =SUMPRODUCT((ACTIVOS!$D$6:$D$15>0)*(ACTIVOS!$D$6:$D$15<=EOMONTH(M$5,0))*(((ACTIVOS!$K$6:$K$15=0)+(ACTIVOS!$K$6:$K$15>M$5))>0)*ACTIVOS!$L$6:$L$15) -> 150 | N16: =SUMPRODUCT((ACTIVOS!$D$6:$D$15>0)*(ACTIVOS!$D$6:$D$15<=EOMONTH(N$5,0))*(((ACTIVOS!$K$6:$K$15=0)+(ACTIVOS!$K$6:$K$15>N$5))>0)*ACTIVOS!$L$6:$L$15) -> 150 | ... AD16: =SUMPRODUCT((ACTIVOS!$D$6:$D$15>0)*(ACTIVOS!$D$6:$D$15<=EOMONTH(AD$5,0))*(((ACTIVOS!$K$6:$K$15=0)+(ACTIVOS!$K$6:$K$15>AD$5))>0)*ACTIVOS!$L$6:$L$15) -> 150 | AE16: =SUM(G16:AD16) -> 3600
A17: CF12 | B17: Seguros, licencias e inspecciones de la flota (desde ACTIVOS) | C17: GENERAL | D17: Otros gastos monetarios | E17: No | F17: =ACTIVOS!N16 -> 85 | G17: =SUMPRODUCT((ACTIVOS!$D$6:$D$15>0)*(ACTIVOS!$D$6:$D$15<=EOMONTH(G$5,0))*(((ACTIVOS!$K$6:$K$15=0)+(ACTIVOS!$K$6:$K$15>G$5))>0)*ACTIVOS!$N$6:$N$15) -> 85 | H17: =SUMPRODUCT((ACTIVOS!$D$6:$D$15>0)*(ACTIVOS!$D$6:$D$15<=EOMONTH(H$5,0))*(((ACTIVOS!$K$6:$K$15=0)+(ACTIVOS!$K$6:$K$15>H$5))>0)*ACTIVOS!$N$6:$N$15) -> 85 | I17: =SUMPRODUCT((ACTIVOS!$D$6:$D$15>0)*(ACTIVOS!$D$6:$D$15<=EOMONTH(I$5,0))*(((ACTIVOS!$K$6:$K$15=0)+(ACTIVOS!$K$6:$K$15>I$5))>0)*ACTIVOS!$N$6:$N$15) -> 85 | J17: =SUMPRODUCT((ACTIVOS!$D$6:$D$15>0)*(ACTIVOS!$D$6:$D$15<=EOMONTH(J$5,0))*(((ACTIVOS!$K$6:$K$15=0)+(ACTIVOS!$K$6:$K$15>J$5))>0)*ACTIVOS!$N$6:$N$15) -> 85 | K17: =SUMPRODUCT((ACTIVOS!$D$6:$D$15>0)*(ACTIVOS!$D$6:$D$15<=EOMONTH(K$5,0))*(((ACTIVOS!$K$6:$K$15=0)+(ACTIVOS!$K$6:$K$15>K$5))>0)*ACTIVOS!$N$6:$N$15) -> 85 | L17: =SUMPRODUCT((ACTIVOS!$D$6:$D$15>0)*(ACTIVOS!$D$6:$D$15<=EOMONTH(L$5,0))*(((ACTIVOS!$K$6:$K$15=0)+(ACTIVOS!$K$6:$K$15>L$5))>0)*ACTIVOS!$N$6:$N$15) -> 85 | M17: =SUMPRODUCT((ACTIVOS!$D$6:$D$15>0)*(ACTIVOS!$D$6:$D$15<=EOMONTH(M$5,0))*(((ACTIVOS!$K$6:$K$15=0)+(ACTIVOS!$K$6:$K$15>M$5))>0)*ACTIVOS!$N$6:$N$15) -> 85 | N17: =SUMPRODUCT((ACTIVOS!$D$6:$D$15>0)*(ACTIVOS!$D$6:$D$15<=EOMONTH(N$5,0))*(((ACTIVOS!$K$6:$K$15=0)+(ACTIVOS!$K$6:$K$15>N$5))>0)*ACTIVOS!$N$6:$N$15) -> 85 | ... AD17: =SUMPRODUCT((ACTIVOS!$D$6:$D$15>0)*(ACTIVOS!$D$6:$D$15<=EOMONTH(AD$5,0))*(((ACTIVOS!$K$6:$K$15=0)+(ACTIVOS!$K$6:$K$15>AD$5))>0)*ACTIVOS!$N$6:$N$15) -> 85 | AE17: =SUM(G17:AD17) -> 2040
A18: CF13 | B18: Otros gastos fijos generales | C18: GENERAL | D18: Otros gastos monetarios | E18: No | F18: 0 | G18: =$F18 -> 0 | H18: =$F18 -> 0 | I18: =$F18 -> 0 | J18: =$F18 -> 0 | K18: =$F18 -> 0 | L18: =$F18 -> 0 | M18: =$F18 -> 0 | N18: =$F18 -> 0 | ... AD18: =$F18 -> 0 | AE18: =SUM(G18:AD18) -> 0
A19: CF14 | B19: Occidente – chofer (servicio contratado) | C19: OCC | D19: Otros gastos monetarios | E19: No | F19: 120 | G19: =$F19 -> 120 | H19: =$F19 -> 120 | I19: =$F19 -> 120 | J19: =$F19 -> 120 | K19: =$F19 -> 120 | L19: =$F19 -> 120 | M19: =$F19 -> 120 | N19: =$F19 -> 120 | ... AD19: =$F19 -> 120 | AE19: =SUM(G19:AD19) -> 2880
A20: CF15 | B20: Occidente – ayudante (servicio contratado) | C20: OCC | D20: Otros gastos monetarios | E20: No | F20: 80 | G20: =$F20 -> 80 | H20: =$F20 -> 80 | I20: =$F20 -> 80 | J20: =$F20 -> 80 | K20: =$F20 -> 80 | L20: =$F20 -> 80 | M20: =$F20 -> 80 | N20: =$F20 -> 80 | ... AD20: =$F20 -> 80 | AE20: =SUM(G20:AD20) -> 1920
A21: CF16 | B21: Occidente – otros gastos fijos | C21: OCC | D21: Otros gastos monetarios | E21: No | F21: 0 | G21: =$F21 -> 0 | H21: =$F21 -> 0 | I21: =$F21 -> 0 | J21: =$F21 -> 0 | K21: =$F21 -> 0 | L21: =$F21 -> 0 | M21: =$F21 -> 0 | N21: =$F21 -> 0 | ... AD21: =$F21 -> 0 | AE21: =SUM(G21:AD21) -> 0
A22: CF17 | B22: Centro – chofer (servicio contratado) | C22: CEN | D22: Otros gastos monetarios | E22: No | F22: 120 | G22: =$F22 -> 120 | H22: =$F22 -> 120 | I22: =$F22 -> 120 | J22: =$F22 -> 120 | K22: =$F22 -> 120 | L22: =$F22 -> 120 | M22: =$F22 -> 120 | N22: =$F22 -> 120 | ... AD22: =$F22 -> 120 | AE22: =SUM(G22:AD22) -> 2880
A23: CF18 | B23: Centro – ayudante (servicio contratado) | C23: CEN | D23: Otros gastos monetarios | E23: No | F23: 80 | G23: =$F23 -> 80 | H23: =$F23 -> 80 | I23: =$F23 -> 80 | J23: =$F23 -> 80 | K23: =$F23 -> 80 | L23: =$F23 -> 80 | M23: =$F23 -> 80 | N23: =$F23 -> 80 | ... AD23: =$F23 -> 80 | AE23: =SUM(G23:AD23) -> 1920
A24: CF19 | B24: Centro – otros gastos fijos (centro transitorio) | C24: CEN | D24: Otros gastos monetarios | E24: No | F24: 0 | G24: =$F24 -> 0 | H24: =$F24 -> 0 | I24: =$F24 -> 0 | J24: =$F24 -> 0 | K24: =$F24 -> 0 | L24: =$F24 -> 0 | M24: =$F24 -> 0 | N24: =$F24 -> 0 | ... AD24: =$F24 -> 0 | AE24: =SUM(G24:AD24) -> 0
A25: CF20 | B25: Oriente – chofer (servicio contratado) | C25: ORI | D25: Otros gastos monetarios | E25: No | F25: 120 | G25: =$F25 -> 120 | H25: =$F25 -> 120 | I25: =$F25 -> 120 | J25: =$F25 -> 120 | K25: =$F25 -> 120 | L25: =$F25 -> 120 | M25: =$F25 -> 120 | N25: =$F25 -> 120 | ... AD25: =$F25 -> 120 | AE25: =SUM(G25:AD25) -> 2880
A26: CF21 | B26: Oriente – ayudante (servicio contratado) | C26: ORI | D26: Otros gastos monetarios | E26: No | F26: 80 | G26: =$F26 -> 80 | H26: =$F26 -> 80 | I26: =$F26 -> 80 | J26: =$F26 -> 80 | K26: =$F26 -> 80 | L26: =$F26 -> 80 | M26: =$F26 -> 80 | N26: =$F26 -> 80 | ... AD26: =$F26 -> 80 | AE26: =SUM(G26:AD26) -> 1920
A27: CF22 | B27: Oriente – otros gastos fijos (centro transitorio) | C27: ORI | D27: Otros gastos monetarios | E27: No | F27: 0 | G27: =$F27 -> 0 | H27: =$F27 -> 0 | I27: =$F27 -> 0 | J27: =$F27 -> 0 | K27: =$F27 -> 0 | L27: =$F27 -> 0 | M27: =$F27 -> 0 | N27: =$F27 -> 0 | ... AD27: =$F27 -> 0 | AE27: =SUM(G27:AD27) -> 0
B28: Tributos sobre salarios de trabajadores propios (calculados)
A29: SS-GENERAL | B29: Contribución a la seguridad social – GENERAL | C29: GENERAL | D29: Gastos de fuerza de trabajo | E29: — | F29: =Contrib_SS*SUMIFS($F$6:$F$27,$C$6:$C$27,$C29,$E$6:$E$27,"Sí") -> 190.4 | G29: =Contrib_SS*SUMIFS(G$6:G$27,$C$6:$C$27,$C29,$E$6:$E$27,"Sí") -> 190.4 | H29: =Contrib_SS*SUMIFS(H$6:H$27,$C$6:$C$27,$C29,$E$6:$E$27,"Sí") -> 190.4 | I29: =Contrib_SS*SUMIFS(I$6:I$27,$C$6:$C$27,$C29,$E$6:$E$27,"Sí") -> 190.4 | J29: =Contrib_SS*SUMIFS(J$6:J$27,$C$6:$C$27,$C29,$E$6:$E$27,"Sí") -> 190.4 | K29: =Contrib_SS*SUMIFS(K$6:K$27,$C$6:$C$27,$C29,$E$6:$E$27,"Sí") -> 190.4 | L29: =Contrib_SS*SUMIFS(L$6:L$27,$C$6:$C$27,$C29,$E$6:$E$27,"Sí") -> 190.4 | M29: =Contrib_SS*SUMIFS(M$6:M$27,$C$6:$C$27,$C29,$E$6:$E$27,"Sí") -> 190.4 | N29: =Contrib_SS*SUMIFS(N$6:N$27,$C$6:$C$27,$C29,$E$6:$E$27,"Sí") -> 190.4 | ... AD29: =Contrib_SS*SUMIFS(AD$6:AD$27,$C$6:$C$27,$C29,$E$6:$E$27,"Sí") -> 190.4 | AE29: =SUM(G29:AD29) -> 4569.6
A30: FT-GENERAL | B30: Impuesto por utilización de la fuerza de trabajo – GENERAL | C30: GENERAL | D30: Gastos de fuerza de trabajo | E30: — | F30: =Imp_Fuerza_Trabajo*SUMIFS($F$6:$F$27,$C$6:$C$27,$C30,$E$6:$E$27,"Sí") -> 68 | G30: =Imp_Fuerza_Trabajo*SUMIFS(G$6:G$27,$C$6:$C$27,$C30,$E$6:$E$27,"Sí") -> 68 | H30: =Imp_Fuerza_Trabajo*SUMIFS(H$6:H$27,$C$6:$C$27,$C30,$E$6:$E$27,"Sí") -> 68 | I30: =Imp_Fuerza_Trabajo*SUMIFS(I$6:I$27,$C$6:$C$27,$C30,$E$6:$E$27,"Sí") -> 68 | J30: =Imp_Fuerza_Trabajo*SUMIFS(J$6:J$27,$C$6:$C$27,$C30,$E$6:$E$27,"Sí") -> 68 | K30: =Imp_Fuerza_Trabajo*SUMIFS(K$6:K$27,$C$6:$C$27,$C30,$E$6:$E$27,"Sí") -> 68 | L30: =Imp_Fuerza_Trabajo*SUMIFS(L$6:L$27,$C$6:$C$27,$C30,$E$6:$E$27,"Sí") -> 68 | M30: =Imp_Fuerza_Trabajo*SUMIFS(M$6:M$27,$C$6:$C$27,$C30,$E$6:$E$27,"Sí") -> 68 | N30: =Imp_Fuerza_Trabajo*SUMIFS(N$6:N$27,$C$6:$C$27,$C30,$E$6:$E$27,"Sí") -> 68 | ... AD30: =Imp_Fuerza_Trabajo*SUMIFS(AD$6:AD$27,$C$6:$C$27,$C30,$E$6:$E$27,"Sí") -> 68 | AE30: =SUM(G30:AD30) -> 1632
A31: SS-OCC | B31: Contribución a la seguridad social – OCC | C31: OCC | D31: Gastos de fuerza de trabajo | E31: — | F31: =Contrib_SS*SUMIFS($F$6:$F$27,$C$6:$C$27,$C31,$E$6:$E$27,"Sí") -> 0 | G31: =Contrib_SS*SUMIFS(G$6:G$27,$C$6:$C$27,$C31,$E$6:$E$27,"Sí") -> 0 | H31: =Contrib_SS*SUMIFS(H$6:H$27,$C$6:$C$27,$C31,$E$6:$E$27,"Sí") -> 0 | I31: =Contrib_SS*SUMIFS(I$6:I$27,$C$6:$C$27,$C31,$E$6:$E$27,"Sí") -> 0 | J31: =Contrib_SS*SUMIFS(J$6:J$27,$C$6:$C$27,$C31,$E$6:$E$27,"Sí") -> 0 | K31: =Contrib_SS*SUMIFS(K$6:K$27,$C$6:$C$27,$C31,$E$6:$E$27,"Sí") -> 0 | L31: =Contrib_SS*SUMIFS(L$6:L$27,$C$6:$C$27,$C31,$E$6:$E$27,"Sí") -> 0 | M31: =Contrib_SS*SUMIFS(M$6:M$27,$C$6:$C$27,$C31,$E$6:$E$27,"Sí") -> 0 | N31: =Contrib_SS*SUMIFS(N$6:N$27,$C$6:$C$27,$C31,$E$6:$E$27,"Sí") -> 0 | ... AD31: =Contrib_SS*SUMIFS(AD$6:AD$27,$C$6:$C$27,$C31,$E$6:$E$27,"Sí") -> 0 | AE31: =SUM(G31:AD31) -> 0
A32: FT-OCC | B32: Impuesto por utilización de la fuerza de trabajo – OCC | C32: OCC | D32: Gastos de fuerza de trabajo | E32: — | F32: =Imp_Fuerza_Trabajo*SUMIFS($F$6:$F$27,$C$6:$C$27,$C32,$E$6:$E$27,"Sí") -> 0 | G32: =Imp_Fuerza_Trabajo*SUMIFS(G$6:G$27,$C$6:$C$27,$C32,$E$6:$E$27,"Sí") -> 0 | H32: =Imp_Fuerza_Trabajo*SUMIFS(H$6:H$27,$C$6:$C$27,$C32,$E$6:$E$27,"Sí") -> 0 | I32: =Imp_Fuerza_Trabajo*SUMIFS(I$6:I$27,$C$6:$C$27,$C32,$E$6:$E$27,"Sí") -> 0 | J32: =Imp_Fuerza_Trabajo*SUMIFS(J$6:J$27,$C$6:$C$27,$C32,$E$6:$E$27,"Sí") -> 0 | K32: =Imp_Fuerza_Trabajo*SUMIFS(K$6:K$27,$C$6:$C$27,$C32,$E$6:$E$27,"Sí") -> 0 | L32: =Imp_Fuerza_Trabajo*SUMIFS(L$6:L$27,$C$6:$C$27,$C32,$E$6:$E$27,"Sí") -> 0 | M32: =Imp_Fuerza_Trabajo*SUMIFS(M$6:M$27,$C$6:$C$27,$C32,$E$6:$E$27,"Sí") -> 0 | N32: =Imp_Fuerza_Trabajo*SUMIFS(N$6:N$27,$C$6:$C$27,$C32,$E$6:$E$27,"Sí") -> 0 | ... AD32: =Imp_Fuerza_Trabajo*SUMIFS(AD$6:AD$27,$C$6:$C$27,$C32,$E$6:$E$27,"Sí") -> 0 | AE32: =SUM(G32:AD32) -> 0
A33: SS-CEN | B33: Contribución a la seguridad social – CEN | C33: CEN | D33: Gastos de fuerza de trabajo | E33: — | F33: =Contrib_SS*SUMIFS($F$6:$F$27,$C$6:$C$27,$C33,$E$6:$E$27,"Sí") -> 0 | G33: =Contrib_SS*SUMIFS(G$6:G$27,$C$6:$C$27,$C33,$E$6:$E$27,"Sí") -> 0 | H33: =Contrib_SS*SUMIFS(H$6:H$27,$C$6:$C$27,$C33,$E$6:$E$27,"Sí") -> 0 | I33: =Contrib_SS*SUMIFS(I$6:I$27,$C$6:$C$27,$C33,$E$6:$E$27,"Sí") -> 0 | J33: =Contrib_SS*SUMIFS(J$6:J$27,$C$6:$C$27,$C33,$E$6:$E$27,"Sí") -> 0 | K33: =Contrib_SS*SUMIFS(K$6:K$27,$C$6:$C$27,$C33,$E$6:$E$27,"Sí") -> 0 | L33: =Contrib_SS*SUMIFS(L$6:L$27,$C$6:$C$27,$C33,$E$6:$E$27,"Sí") -> 0 | M33: =Contrib_SS*SUMIFS(M$6:M$27,$C$6:$C$27,$C33,$E$6:$E$27,"Sí") -> 0 | N33: =Contrib_SS*SUMIFS(N$6:N$27,$C$6:$C$27,$C33,$E$6:$E$27,"Sí") -> 0 | ... AD33: =Contrib_SS*SUMIFS(AD$6:AD$27,$C$6:$C$27,$C33,$E$6:$E$27,"Sí") -> 0 | AE33: =SUM(G33:AD33) -> 0
A34: FT-CEN | B34: Impuesto por utilización de la fuerza de trabajo – CEN | C34: CEN | D34: Gastos de fuerza de trabajo | E34: — | F34: =Imp_Fuerza_Trabajo*SUMIFS($F$6:$F$27,$C$6:$C$27,$C34,$E$6:$E$27,"Sí") -> 0 | G34: =Imp_Fuerza_Trabajo*SUMIFS(G$6:G$27,$C$6:$C$27,$C34,$E$6:$E$27,"Sí") -> 0 | H34: =Imp_Fuerza_Trabajo*SUMIFS(H$6:H$27,$C$6:$C$27,$C34,$E$6:$E$27,"Sí") -> 0 | I34: =Imp_Fuerza_Trabajo*SUMIFS(I$6:I$27,$C$6:$C$27,$C34,$E$6:$E$27,"Sí") -> 0 | J34: =Imp_Fuerza_Trabajo*SUMIFS(J$6:J$27,$C$6:$C$27,$C34,$E$6:$E$27,"Sí") -> 0 | K34: =Imp_Fuerza_Trabajo*SUMIFS(K$6:K$27,$C$6:$C$27,$C34,$E$6:$E$27,"Sí") -> 0 | L34: =Imp_Fuerza_Trabajo*SUMIFS(L$6:L$27,$C$6:$C$27,$C34,$E$6:$E$27,"Sí") -> 0 | M34: =Imp_Fuerza_Trabajo*SUMIFS(M$6:M$27,$C$6:$C$27,$C34,$E$6:$E$27,"Sí") -> 0 | N34: =Imp_Fuerza_Trabajo*SUMIFS(N$6:N$27,$C$6:$C$27,$C34,$E$6:$E$27,"Sí") -> 0 | ... AD34: =Imp_Fuerza_Trabajo*SUMIFS(AD$6:AD$27,$C$6:$C$27,$C34,$E$6:$E$27,"Sí") -> 0 | AE34: =SUM(G34:AD34) -> 0
A35: SS-ORI | B35: Contribución a la seguridad social – ORI | C35: ORI | D35: Gastos de fuerza de trabajo | E35: — | F35: =Contrib_SS*SUMIFS($F$6:$F$27,$C$6:$C$27,$C35,$E$6:$E$27,"Sí") -> 0 | G35: =Contrib_SS*SUMIFS(G$6:G$27,$C$6:$C$27,$C35,$E$6:$E$27,"Sí") -> 0 | H35: =Contrib_SS*SUMIFS(H$6:H$27,$C$6:$C$27,$C35,$E$6:$E$27,"Sí") -> 0 | I35: =Contrib_SS*SUMIFS(I$6:I$27,$C$6:$C$27,$C35,$E$6:$E$27,"Sí") -> 0 | J35: =Contrib_SS*SUMIFS(J$6:J$27,$C$6:$C$27,$C35,$E$6:$E$27,"Sí") -> 0 | K35: =Contrib_SS*SUMIFS(K$6:K$27,$C$6:$C$27,$C35,$E$6:$E$27,"Sí") -> 0 | L35: =Contrib_SS*SUMIFS(L$6:L$27,$C$6:$C$27,$C35,$E$6:$E$27,"Sí") -> 0 | M35: =Contrib_SS*SUMIFS(M$6:M$27,$C$6:$C$27,$C35,$E$6:$E$27,"Sí") -> 0 | N35: =Contrib_SS*SUMIFS(N$6:N$27,$C$6:$C$27,$C35,$E$6:$E$27,"Sí") -> 0 | ... AD35: =Contrib_SS*SUMIFS(AD$6:AD$27,$C$6:$C$27,$C35,$E$6:$E$27,"Sí") -> 0 | AE35: =SUM(G35:AD35) -> 0
A36: FT-ORI | B36: Impuesto por utilización de la fuerza de trabajo – ORI | C36: ORI | D36: Gastos de fuerza de trabajo | E36: — | F36: =Imp_Fuerza_Trabajo*SUMIFS($F$6:$F$27,$C$6:$C$27,$C36,$E$6:$E$27,"Sí") -> 0 | G36: =Imp_Fuerza_Trabajo*SUMIFS(G$6:G$27,$C$6:$C$27,$C36,$E$6:$E$27,"Sí") -> 0 | H36: =Imp_Fuerza_Trabajo*SUMIFS(H$6:H$27,$C$6:$C$27,$C36,$E$6:$E$27,"Sí") -> 0 | I36: =Imp_Fuerza_Trabajo*SUMIFS(I$6:I$27,$C$6:$C$27,$C36,$E$6:$E$27,"Sí") -> 0 | J36: =Imp_Fuerza_Trabajo*SUMIFS(J$6:J$27,$C$6:$C$27,$C36,$E$6:$E$27,"Sí") -> 0 | K36: =Imp_Fuerza_Trabajo*SUMIFS(K$6:K$27,$C$6:$C$27,$C36,$E$6:$E$27,"Sí") -> 0 | L36: =Imp_Fuerza_Trabajo*SUMIFS(L$6:L$27,$C$6:$C$27,$C36,$E$6:$E$27,"Sí") -> 0 | M36: =Imp_Fuerza_Trabajo*SUMIFS(M$6:M$27,$C$6:$C$27,$C36,$E$6:$E$27,"Sí") -> 0 | N36: =Imp_Fuerza_Trabajo*SUMIFS(N$6:N$27,$C$6:$C$27,$C36,$E$6:$E$27,"Sí") -> 0 | ... AD36: =Imp_Fuerza_Trabajo*SUMIFS(AD$6:AD$27,$C$6:$C$27,$C36,$E$6:$E$27,"Sí") -> 0 | AE36: =SUM(G36:AD36) -> 0
B38: TOTAL FIJOS GENERALES (se reparten entre todos los kg) | C38: GENERAL | F38: =SUMIF($C$6:$C$36,"GENERAL",$F$6:$F$36) -> 2640.0667 | G38: =SUMIF($C$6:$C$36,"GENERAL",G$6:G$36) -> 2640.0667 | H38: =SUMIF($C$6:$C$36,"GENERAL",H$6:H$36) -> 2640.0667 | I38: =SUMIF($C$6:$C$36,"GENERAL",I$6:I$36) -> 2640.0667 | J38: =SUMIF($C$6:$C$36,"GENERAL",J$6:J$36) -> 2640.0667 | K38: =SUMIF($C$6:$C$36,"GENERAL",K$6:K$36) -> 2640.0667 | L38: =SUMIF($C$6:$C$36,"GENERAL",L$6:L$36) -> 2640.0667 | M38: =SUMIF($C$6:$C$36,"GENERAL",M$6:M$36) -> 2640.0667 | N38: =SUMIF($C$6:$C$36,"GENERAL",N$6:N$36) -> 2640.0667 | ... AE38: =SUMIF($C$6:$C$36,"GENERAL",AE$6:AE$36) -> 63361.6
